import CppLib

public func call_cpp() {
  f_with_exceptions()
  print("I called it successfully")
}